<?xml version="1.0"?>

<robot name="bumperbot" xmlns:xacro="http://ros.org/wiki/xacro">

  <link name="base_footprint"/>

  <link name="base_link">
    <visual>
      <origin xyz="0 0 0" rpy="0 0 0"/>
      <geometry>
        <mesh filename="package://bumperbot_description/meshes/sasi.STL" scale="0.001 0.001 0.001"/>
      </geometry>
    </visual>
  </link>

  <joint name="base_joint" type="fixed">
    <parent link="base_footprint"/>
    <child link="base_link"/>
    <origin xyz="0 0 0.033" rpy="0 0 0"/>
  </joint>

  <link name="wheel_right_link">
    <visual>
      <origin xyz="0 -0.014 0" rpy="1.5708 0 0"/>
      <geometry>
        <mesh filename="package://bumperbot_description/meshes/wheel_right_link.STL"/>
      </geometry>
    </visual>
  </link>

  <joint name="wheel_right_joint" type="continuous">
    <parent link="base_link"/>
    <child link="wheel_right_link"/>
    <axis xyz="0 1 0"/>
    <origin xyz="0 -0.0701101849418637 0" rpy="0 0 0"/>
  </joint>

  <link name="wheel_left_link">
    <visual>
      <origin xyz="0 0.014 0" rpy="1.5708 0 3.1416"/>
      <geometry>
        <mesh filename="package://bumperbot_description/meshes/wheel_left_link.STL"/>
      </geometry>
    </visual>
  </link>

  <joint name="wheel_left_joint" type="continuous">
    <parent link="base_link"/>
    <child link="wheel_left_link"/>
    <axis xyz="0 1 0"/>
    <origin xyz="0 0.0701101849418637 0" rpy="0 0 0"/>
  </joint>


</robot>